<?xml version="1.0" encoding="utf-8"?>
<!-- This URDF was automatically created by SolidWorks to URDF Exporter! Originally created by Stephen Brawner (brawner@gmail.com) 
     Commit Version: 1.6.0-4-g7f85cfe  Build Version: 1.6.7995.38578
     For more information, please see http://wiki.ros.org/sw_urdf_exporter -->
<robot
  name="robusta_urdf11">
  <link
    name="base_link">
    <inertial>
      <origin
        xyz="-0.017309 -0.00039036 0.34584"
        rpy="0 0 0" />
      <mass
        value="9.3634" />
      <inertia
        ixx="0.11856"
        ixy="4.9396E-05"
        ixz="0.0027062"
        iyy="0.09508"
        iyz="1.0793E-05"
        izz="0.16874" />
    </inertial>
    <visual>
      <origin
        xyz="0 0 0"
        rpy="0 0 0" />
      <geometry>
        <mesh
          filename="package://robusta_urdf11/meshes/base_link.STL" />
      </geometry>
      <material
        name="">
        <color
          rgba="0.75294 0.75294 0.75294 1" />
      </material>
    </visual>
    <collision>
      <origin
        xyz="0 0 0"
        rpy="0 0 0" />
      <geometry>
        <mesh
          filename="package://robusta_urdf11/meshes/base_link.STL" />
      </geometry>
    </collision>
  </link>
  <link
    name="right_wheel">
    <inertial>
      <origin
        xyz="-1.9082E-17 0.029996 -1.1102E-16"
        rpy="0 0 0" />
      <mass
        value="0.79627" />
      <inertia
        ixx="0.00108"
        ixy="-4.9001E-19"
        ixz="6.1E-20"
        iyy="0.0016824"
        iyz="5.749E-20"
        izz="0.00108" />
    </inertial>
    <visual>
      <origin
        xyz="0 0 0"
        rpy="0 0 0" />
      <geometry>
        <mesh
          filename="package://robusta_urdf11/meshes/right_wheel.STL" />
      </geometry>
      <material
        name="">
        <color
          rgba="0.7451 0.7451 0.7451 1" />
      </material>
    </visual>
    <collision>
      <origin
        xyz="0 0 0"
        rpy="0 0 0" />
      <geometry>
        <mesh
          filename="package://robusta_urdf11/meshes/right_wheel.STL" />
      </geometry>
    </collision>
  </link>
  <joint
    name="right_wheel_joint"
    type="continuous">
    <origin
      xyz="0.00011731 -0.229 0.02275"
      rpy="0 0 0" />
    <parent
      link="base_link" />
    <child
      link="right_wheel" />
    <axis
      xyz="0 1 0" />
  </joint>
  <link
    name="left_wheel">
    <inertial>
      <origin
        xyz="1.0408E-17 -0.029996 1.0495E-16"
        rpy="0 0 0" />
      <mass
        value="0.79627" />
      <inertia
        ixx="0.00108"
        ixy="-5.5756E-19"
        ixz="-8.8001E-20"
        iyy="0.0016824"
        iyz="-1.0208E-22"
        izz="0.00108" />
    </inertial>
    <visual>
      <origin
        xyz="0 0 0"
        rpy="0 0 0" />
      <geometry>
        <mesh
          filename="package://robusta_urdf11/meshes/left_wheel.STL" />
      </geometry>
      <material
        name="">
        <color
          rgba="0.7451 0.7451 0.7451 1" />
      </material>
    </visual>
    <collision>
      <origin
        xyz="0 0 0"
        rpy="0 0 0" />
      <geometry>
        <mesh
          filename="package://robusta_urdf11/meshes/left_wheel.STL" />
      </geometry>
    </collision>
  </link>
  <joint
    name="left_wheel_joint"
    type="continuous">
    <origin
      xyz="0.00011731 0.22893 0.02275"
      rpy="0 0 0" />
    <parent
      link="base_link" />
    <child
      link="left_wheel" />
    <axis
      xyz="0 1 0" />
  </joint>
  <link
    name="front_caster">
    <inertial>
      <origin
        xyz="2.7756E-17 6.9389E-18 0.015185"
        rpy="0 0 0" />
      <mass
        value="0.047631" />
      <inertia
        ixx="1.1805E-05"
        ixy="1.3062E-21"
        ixz="-3.6492E-21"
        iyy="1.061E-05"
        iyz="-8.9479E-22"
        izz="1.0463E-05" />
    </inertial>
    <visual>
      <origin
        xyz="0 0 0"
        rpy="0 0 0" />
      <geometry>
        <mesh
          filename="package://robusta_urdf11/meshes/front_caster.STL" />
      </geometry>
      <material
        name="">
        <color
          rgba="0.7451 0.7451 0.7451 1" />
      </material>
    </visual>
    <collision>
      <origin
        xyz="0 0 0"
        rpy="0 0 0" />
      <geometry>
        <mesh
          filename="package://robusta_urdf11/meshes/front_caster.STL" />
      </geometry>
    </collision>
  </link>
  <joint
    name="front_caster_joint"
    type="fixed">
    <origin
      xyz="0.17412 -3.2924E-05 -0.03225"
      rpy="0 0 0" />
    <parent
      link="base_link" />
    <child
      link="front_caster" />
    <axis
      xyz="0 0 0" />
  </joint>
  <link
    name="back_caster">
    <inertial>
      <origin
        xyz="0 1.0408E-17 0.015185"
        rpy="0 0 0" />
      <mass
        value="0.047631" />
      <inertia
        ixx="1.1805E-05"
        ixy="1.2065E-21"
        ixz="-3.5764E-21"
        iyy="1.061E-05"
        iyz="-8.9479E-22"
        izz="1.0463E-05" />
    </inertial>
    <visual>
      <origin
        xyz="0 0 0"
        rpy="0 0 0" />
      <geometry>
        <mesh
          filename="package://robusta_urdf11/meshes/back_caster.STL" />
      </geometry>
      <material
        name="">
        <color
          rgba="0.7451 0.7451 0.7451 1" />
      </material>
    </visual>
    <collision>
      <origin
        xyz="0 0 0"
        rpy="0 0 0" />
      <geometry>
        <mesh
          filename="package://robusta_urdf11/meshes/back_caster.STL" />
      </geometry>
    </collision>
  </link>
  <joint
    name="back_caster_joint"
    type="fixed">
    <origin
      xyz="-0.17388 -3.2924E-05 -0.03225"
      rpy="0 0 0" />
    <parent
      link="base_link" />
    <child
      link="back_caster" />
    <axis
      xyz="0 0 0" />
  </joint>
  <gazebo reference="front_caster">
   <mu1>0.01</mu1>
   <mu2>0.01</mu2>
   <material>Gazebo/White</material>
 </gazebo>
   <gazebo reference="back_caster">
   <mu1>0.01</mu1>
   <mu2>0.01</mu2>
   <material>Gazebo/White</material>
 </gazebo>
  	<link name="laser_link">
    <inertial>
      <origin
        xyz="-0.017309 -0.00039036 0.5"
        rpy="0 0 0" />
      <mass
        value="0.047631" />
      <inertia
        ixx="1.1805E-05"
        ixy="1.2065E-21"
        ixz="-3.5764E-21"
        iyy="1.061E-05"
        iyz="-8.9479E-22"
        izz="1.0463E-05" />
    </inertial>
    <visual>
      <origin
        xyz="0 0 0"
        rpy="0 0 0" />
      <geometry>
        <mesh
          filename="package://robusta_urdf11/meshes/rp_lidar_meshmixer.STL" />
      </geometry>
      <material
        name="">
        <color
          rgba="0.7451 0.7451 0.7451 1" />
      </material>
    </visual>
        <collision>
      <origin
        xyz="0 0 0"
        rpy="0 0 0" />
      <geometry>
        <mesh
          filename="package://robusta_urdf11/meshes/rp_lidar_meshmixer.STL" />
      </geometry>
    </collision>
  </link>
  
  <joint name="laser_joint" type="fixed">
    <origin xyz="-0.13309 -0.00039036 0.8999" rpy="0 0 0" />
    <parent link="base_link"/>
    <child link="laser_link" />
  </joint>
  <gazebo reference="laser_link">
    <material>Gazebo/Blue</material>
    <turnGravityOff>false</turnGravityOff>
    <sensor type="ray" name="laser_link">
      <pose>0 0 0 0 0 0</pose>
      <visualize>false</visualize>
      <update_rate>40</update_rate>
      <ray>
        <scan>
          <horizontal>
            <samples>720</samples>
            <resolution>1</resolution>
            <min_angle>-3.14</min_angle>
            <max_angle>3.14</max_angle>
          </horizontal>
        </scan>
        <range>
          <min>0.10</min>
          <max>12.0</max>
          <resolution>0.001</resolution>
        </range>
      </ray>
      
      <plugin name="lasser_sensor_plugin" filename="libgazebo_ros_laser.so">
        <topicName>/scan</topicName>
        <frameName>laser_link</frameName>
      </plugin>
    </sensor>
  </gazebo>
  	<gazebo>
  	<plugin name="differential_drive_controller" filename="libgazebo_ros_diff_drive.so">
	    <legacyMode>true</legacyMode>
	    <rosDebugLevel>Debug</rosDebugLevel>
	    <publishWheelTF>false</publishWheelTF>
	    <robotNamespace>/</robotNamespace>
	    <publishTf>1</publishTf>
	    <publishWheelJointState>false</publishWheelJointState>
	    <alwaysOn>true</alwaysOn>
	    <updateRate>100.0</updateRate>
	    <leftJoint>left_wheel_joint</leftJoint>
	    <rightJoint>right_wheel_joint</rightJoint>
	    <wheelSeparation>0.35</wheelSeparation>
	    <wheelDiameter>0.12</wheelDiameter>
	    <broadcastTF>1</broadcastTF>
	    <wheelTorque>30</wheelTorque>
	    <wheelAcceleration>1.8</wheelAcceleration>
	    <commandTopic>cmd_vel</commandTopic>
	    <odometryFrame>odom</odometryFrame> 
	    <odometryTopic>odom</odometryTopic> 
	    <robotBaseFrame>base_link</robotBaseFrame>
   </plugin>
  </gazebo> 
</robot>
